<robot name="roomba">

  <link name="base_link"/>

  <link name="body_link">
    <visual>
      <geometry>
        <cylinder radius="0.15" length="0.072"/>
      </geometry>
      <origin xyz="0 0 0" rpy="0 0 0"/>
      <material name="white">
        <color rgba="1.0 1.0 1.0 2.0"/>
      </material>
    </visual>
  </link>

  <link name="ball_link_front">
    <visual>
      <geometry>
        <sphere radius="0.01"/>
      </geometry>
      <origin xyz="0 0 0" rpy="0 0 0"/>
      <material name="white">
        <color rgba="1.0 1.0 1.0 2.0"/>
      </material>
    </visual>
  </link>

  <link name="ball_link_back">
    <visual>
      <geometry>
        <sphere radius="0.01"/>
      </geometry>
      <origin xyz="0 0 0" rpy="0 0 0"/>
      <material name="white">
        <color rgba="1.0 1.0 1.0 2.0"/>
      </material>
    </visual>
  </link>

  <link name="wheel_link_right">
    <visual>
      <geometry>
        <cylinder radius="0.036" length="0.016"/>
      </geometry>
      <origin xyz="0 0 0" rpy="0 0 0"/>
      <material name="black">
        <color rgba="0.0 0.0 0.0 2.0"/>
      </material>
    </visual>
  </link>

  <link name="wheel_link_left">
    <visual>
      <geometry>
        <cylinder radius="0.036" length="0.016"/>
      </geometry>
      <origin xyz="0 0 0" rpy="0 0 0"/>
      <material name="black">
        <color rgba="0.0 0.0 0.0 2.0"/>
      </material>
    </visual>
  </link>
  
  <joint name="body_joint" type="fixed">
    <parent link="base_link"/>
    <child  link="body_link"/>
    <origin xyz="0 0 0.046" rpy="0 0 0" />
  </joint>

  <joint name="ball_joint_front" type="fixed">
    <parent link="body_link"/>
    <child  link="ball_link_front"/>
    <origin xyz="0.11 0 -0.036" rpy="0 0 0" />
  </joint>

  <joint name="ball_joint_back" type="fixed">
    <parent link="body_link"/>
    <child  link="ball_link_back"/>
    <origin xyz="-0.11 0 -0.036" rpy="0 0 0" />
  </joint>

  <joint name="wheel_joint_right" type="continuous">
    <parent link="body_link"/>
    <child  link="wheel_link_right"/>
    <origin xyz="0 -0.158 -0.01" rpy="1.570796326794897 0 0" />
    <axis xyz="0 0 -1" />
  </joint>

  <joint name="wheel_joint_left" type="continuous">
    <parent link="body_link"/>
    <child  link="wheel_link_left"/>
    <origin xyz="0 0.158 -0.01" rpy="1.570796326794897 0 0" />
    <axis xyz="0 0 -1" />
  </joint>

</robot>